[2024-09-13T13:33:36.588+0000] {local_task_job_runner.py:123} INFO - ::group::Pre task execution logs
[2024-09-13T13:33:36.604+0000] {taskinstance.py:2612} INFO - Dependencies all met for dep_context=non-requeueable deps ti=<TaskInstance: welcome_dag.test manual__2024-09-11T08:45:16.827592+00:00 [queued]>
[2024-09-13T13:33:36.612+0000] {taskinstance.py:2612} INFO - Dependencies all met for dep_context=requeueable deps ti=<TaskInstance: welcome_dag.test manual__2024-09-11T08:45:16.827592+00:00 [queued]>
[2024-09-13T13:33:36.613+0000] {taskinstance.py:2865} INFO - Starting attempt 2 of 2
[2024-09-13T13:33:36.624+0000] {taskinstance.py:2888} INFO - Executing <Task(PythonOperator): test> on 2024-09-11 08:45:16.827592+00:00
[2024-09-13T13:33:36.637+0000] {warnings.py:112} WARNING - /home/***/.local/lib/python3.12/site-packages/***/task/task_runner/standard_task_runner.py:70: DeprecationWarning: This process (pid=458) is multi-threaded, use of fork() may lead to deadlocks in the child.
  pid = os.fork()

[2024-09-13T13:33:36.639+0000] {standard_task_runner.py:72} INFO - Started process 460 to run task
[2024-09-13T13:33:36.639+0000] {standard_task_runner.py:104} INFO - Running: ['***', 'tasks', 'run', 'welcome_dag', 'test', 'manual__2024-09-11T08:45:16.827592+00:00', '--job-id', '45', '--raw', '--subdir', 'DAGS_FOLDER/welcome.py', '--cfg-path', '/tmp/tmpy034876t']
[2024-09-13T13:33:36.640+0000] {standard_task_runner.py:105} INFO - Job 45: Subtask test
[2024-09-13T13:33:36.686+0000] {task_command.py:467} INFO - Running <TaskInstance: welcome_dag.test manual__2024-09-11T08:45:16.827592+00:00 [running]> on host 620abf759a7f
[2024-09-13T13:33:36.761+0000] {taskinstance.py:3131} INFO - Exporting env vars: AIRFLOW_CTX_DAG_OWNER='***' AIRFLOW_CTX_DAG_ID='welcome_dag' AIRFLOW_CTX_TASK_ID='test' AIRFLOW_CTX_EXECUTION_DATE='2024-09-11T08:45:16.827592+00:00' AIRFLOW_CTX_TRY_NUMBER='2' AIRFLOW_CTX_DAG_RUN_ID='manual__2024-09-11T08:45:16.827592+00:00'
[2024-09-13T13:33:36.762+0000] {logging_mixin.py:190} INFO - Task instance is in running state
[2024-09-13T13:33:36.763+0000] {logging_mixin.py:190} INFO -  Previous state of the Task instance: queued
[2024-09-13T13:33:36.763+0000] {logging_mixin.py:190} INFO - Current task name:test state:running start_date:2024-09-13 13:33:36.605194+00:00
[2024-09-13T13:33:36.763+0000] {logging_mixin.py:190} INFO - Dag name:welcome_dag and current dag run status:running
[2024-09-13T13:33:36.764+0000] {taskinstance.py:731} INFO - ::endgroup::
[2024-09-13T13:33:36.774+0000] {warnings.py:112} WARNING - /home/***/.local/lib/python3.12/site-packages/torchvision/models/_utils.py:208: UserWarning: The parameter 'pretrained' is deprecated since 0.13 and may be removed in the future, please use 'weights' instead.
  warnings.warn(

[2024-09-13T13:33:36.775+0000] {warnings.py:112} WARNING - /home/***/.local/lib/python3.12/site-packages/torchvision/models/_utils.py:223: UserWarning: Arguments other than a weight enum or `None` for 'weights' are deprecated since 0.13 and may be removed in the future. The current behavior is equivalent to passing `weights=None`.
  warnings.warn(msg)

[2024-09-13T13:33:37.120+0000] {warnings.py:112} WARNING - /opt/***/dags/welcome.py:168: FutureWarning: You are using `torch.load` with `weights_only=False` (the current default value), which uses the default pickle module implicitly. It is possible to construct malicious pickle data which will execute arbitrary code during unpickling (See https://github.com/pytorch/pytorch/blob/main/SECURITY.md#untrusted-models for more details). In a future release, the default value for `weights_only` will be flipped to `True`. This limits the functions that could be executed during unpickling. Arbitrary objects will no longer be allowed to be loaded via this mode unless they are explicitly allowlisted by the user via `torch.serialization.add_safe_globals`. We recommend you start setting `weights_only=True` for any use case where you don't have full control of the loaded file. Please open an issue on GitHub for any issues related to this experimental feature.
  net.load_state_dict(torch.load(model_path))

[2024-09-13T13:33:37.121+0000] {taskinstance.py:3310} ERROR - Task failed with exception
Traceback (most recent call last):
  File "/home/airflow/.local/lib/python3.12/site-packages/airflow/models/taskinstance.py", line 767, in _execute_task
    result = _execute_callable(context=context, **execute_callable_kwargs)
             ^^^^^^^^^^^^^^^^^^^^^^^^^^^^^^^^^^^^^^^^^^^^^^^^^^^^^^^^^^^^^
  File "/home/airflow/.local/lib/python3.12/site-packages/airflow/models/taskinstance.py", line 733, in _execute_callable
    return ExecutionCallableRunner(
           ^^^^^^^^^^^^^^^^^^^^^^^^
  File "/home/airflow/.local/lib/python3.12/site-packages/airflow/utils/operator_helpers.py", line 252, in run
    return self.func(*args, **kwargs)
           ^^^^^^^^^^^^^^^^^^^^^^^^^^
  File "/home/airflow/.local/lib/python3.12/site-packages/airflow/models/baseoperator.py", line 406, in wrapper
    return func(self, *args, **kwargs)
           ^^^^^^^^^^^^^^^^^^^^^^^^^^^
  File "/home/airflow/.local/lib/python3.12/site-packages/airflow/operators/python.py", line 238, in execute
    return_value = self.execute_callable()
                   ^^^^^^^^^^^^^^^^^^^^^^^
  File "/home/airflow/.local/lib/python3.12/site-packages/airflow/operators/python.py", line 256, in execute_callable
    return runner.run(*self.op_args, **self.op_kwargs)
           ^^^^^^^^^^^^^^^^^^^^^^^^^^^^^^^^^^^^^^^^^^^
  File "/home/airflow/.local/lib/python3.12/site-packages/airflow/utils/operator_helpers.py", line 252, in run
    return self.func(*args, **kwargs)
           ^^^^^^^^^^^^^^^^^^^^^^^^^^
  File "/opt/airflow/dags/welcome.py", line 168, in test
    net.load_state_dict(torch.load(model_path))
                        ^^^^^^^^^^^^^^^^^^^^^^
  File "/home/airflow/.local/lib/python3.12/site-packages/torch/serialization.py", line 1065, in load
    with _open_file_like(f, 'rb') as opened_file:
         ^^^^^^^^^^^^^^^^^^^^^^^^
  File "/home/airflow/.local/lib/python3.12/site-packages/torch/serialization.py", line 468, in _open_file_like
    return _open_file(name_or_buffer, mode)
           ^^^^^^^^^^^^^^^^^^^^^^^^^^^^^^^^
  File "/home/airflow/.local/lib/python3.12/site-packages/torch/serialization.py", line 449, in __init__
    super().__init__(open(name, mode))
                     ^^^^^^^^^^^^^^^^
FileNotFoundError: [Errno 2] No such file or directory: '/tmp/model.pth'
[2024-09-13T13:33:37.134+0000] {logging_mixin.py:190} INFO - Task instance in failure state
[2024-09-13T13:33:37.135+0000] {logging_mixin.py:190} INFO - Task start:2024-09-13 13:33:36.605194+00:00 end:2024-09-13 13:33:37.133720+00:00 duration:0.528526
[2024-09-13T13:33:37.135+0000] {logging_mixin.py:190} INFO - Task:<Task(PythonOperator): test> dag:<DAG: welcome_dag> dagrun:<DagRun welcome_dag @ 2024-09-11 08:45:16.827592+00:00: manual__2024-09-11T08:45:16.827592+00:00, state:running, queued_at: 2024-09-13 13:33:31.816233+00:00. externally triggered: True>
[2024-09-13T13:33:37.135+0000] {logging_mixin.py:190} INFO - Failure caused by [Errno 2] No such file or directory: '/tmp/model.pth'
[2024-09-13T13:33:37.136+0000] {taskinstance.py:1225} INFO - Marking task as FAILED. dag_id=welcome_dag, task_id=test, run_id=manual__2024-09-11T08:45:16.827592+00:00, execution_date=20240911T084516, start_date=20240913T133336, end_date=20240913T133337
[2024-09-13T13:33:37.149+0000] {taskinstance.py:340} INFO - ::group::Post task execution logs
[2024-09-13T13:33:37.150+0000] {standard_task_runner.py:124} ERROR - Failed to execute job 45 for task test ([Errno 2] No such file or directory: '/tmp/model.pth'; 460)
Traceback (most recent call last):
  File "/home/airflow/.local/lib/python3.12/site-packages/airflow/task/task_runner/standard_task_runner.py", line 117, in _start_by_fork
    ret = args.func(args, dag=self.dag)
          ^^^^^^^^^^^^^^^^^^^^^^^^^^^^^
  File "/home/airflow/.local/lib/python3.12/site-packages/airflow/cli/cli_config.py", line 49, in command
    return func(*args, **kwargs)
           ^^^^^^^^^^^^^^^^^^^^^
  File "/home/airflow/.local/lib/python3.12/site-packages/airflow/utils/cli.py", line 115, in wrapper
    return f(*args, **kwargs)
           ^^^^^^^^^^^^^^^^^^
  File "/home/airflow/.local/lib/python3.12/site-packages/airflow/cli/commands/task_command.py", line 483, in task_run
    task_return_code = _run_task_by_selected_method(args, _dag, ti)
                       ^^^^^^^^^^^^^^^^^^^^^^^^^^^^^^^^^^^^^^^^^^^^
  File "/home/airflow/.local/lib/python3.12/site-packages/airflow/cli/commands/task_command.py", line 256, in _run_task_by_selected_method
    return _run_raw_task(args, ti)
           ^^^^^^^^^^^^^^^^^^^^^^^
  File "/home/airflow/.local/lib/python3.12/site-packages/airflow/cli/commands/task_command.py", line 341, in _run_raw_task
    return ti._run_raw_task(
           ^^^^^^^^^^^^^^^^^
  File "/home/airflow/.local/lib/python3.12/site-packages/airflow/utils/session.py", line 97, in wrapper
    return func(*args, session=session, **kwargs)
           ^^^^^^^^^^^^^^^^^^^^^^^^^^^^^^^^^^^^^^
  File "/home/airflow/.local/lib/python3.12/site-packages/airflow/models/taskinstance.py", line 3004, in _run_raw_task
    return _run_raw_task(
           ^^^^^^^^^^^^^^
  File "/home/airflow/.local/lib/python3.12/site-packages/airflow/models/taskinstance.py", line 273, in _run_raw_task
    TaskInstance._execute_task_with_callbacks(
  File "/home/airflow/.local/lib/python3.12/site-packages/airflow/models/taskinstance.py", line 3158, in _execute_task_with_callbacks
    result = self._execute_task(context, task_orig)
             ^^^^^^^^^^^^^^^^^^^^^^^^^^^^^^^^^^^^^^
  File "/home/airflow/.local/lib/python3.12/site-packages/airflow/models/taskinstance.py", line 3182, in _execute_task
    return _execute_task(self, context, task_orig)
           ^^^^^^^^^^^^^^^^^^^^^^^^^^^^^^^^^^^^^^^
  File "/home/airflow/.local/lib/python3.12/site-packages/airflow/models/taskinstance.py", line 767, in _execute_task
    result = _execute_callable(context=context, **execute_callable_kwargs)
             ^^^^^^^^^^^^^^^^^^^^^^^^^^^^^^^^^^^^^^^^^^^^^^^^^^^^^^^^^^^^^
  File "/home/airflow/.local/lib/python3.12/site-packages/airflow/models/taskinstance.py", line 733, in _execute_callable
    return ExecutionCallableRunner(
           ^^^^^^^^^^^^^^^^^^^^^^^^
  File "/home/airflow/.local/lib/python3.12/site-packages/airflow/utils/operator_helpers.py", line 252, in run
    return self.func(*args, **kwargs)
           ^^^^^^^^^^^^^^^^^^^^^^^^^^
  File "/home/airflow/.local/lib/python3.12/site-packages/airflow/models/baseoperator.py", line 406, in wrapper
    return func(self, *args, **kwargs)
           ^^^^^^^^^^^^^^^^^^^^^^^^^^^
  File "/home/airflow/.local/lib/python3.12/site-packages/airflow/operators/python.py", line 238, in execute
    return_value = self.execute_callable()
                   ^^^^^^^^^^^^^^^^^^^^^^^
  File "/home/airflow/.local/lib/python3.12/site-packages/airflow/operators/python.py", line 256, in execute_callable
    return runner.run(*self.op_args, **self.op_kwargs)
           ^^^^^^^^^^^^^^^^^^^^^^^^^^^^^^^^^^^^^^^^^^^
  File "/home/airflow/.local/lib/python3.12/site-packages/airflow/utils/operator_helpers.py", line 252, in run
    return self.func(*args, **kwargs)
           ^^^^^^^^^^^^^^^^^^^^^^^^^^
  File "/opt/airflow/dags/welcome.py", line 168, in test
    net.load_state_dict(torch.load(model_path))
                        ^^^^^^^^^^^^^^^^^^^^^^
  File "/home/airflow/.local/lib/python3.12/site-packages/torch/serialization.py", line 1065, in load
    with _open_file_like(f, 'rb') as opened_file:
         ^^^^^^^^^^^^^^^^^^^^^^^^
  File "/home/airflow/.local/lib/python3.12/site-packages/torch/serialization.py", line 468, in _open_file_like
    return _open_file(name_or_buffer, mode)
           ^^^^^^^^^^^^^^^^^^^^^^^^^^^^^^^^
  File "/home/airflow/.local/lib/python3.12/site-packages/torch/serialization.py", line 449, in __init__
    super().__init__(open(name, mode))
                     ^^^^^^^^^^^^^^^^
FileNotFoundError: [Errno 2] No such file or directory: '/tmp/model.pth'
[2024-09-13T13:33:37.175+0000] {local_task_job_runner.py:266} INFO - Task exited with return code 1
[2024-09-13T13:33:37.189+0000] {taskinstance.py:3900} INFO - 0 downstream tasks scheduled from follow-on schedule check
[2024-09-13T13:33:37.192+0000] {local_task_job_runner.py:245} INFO - ::endgroup::
